<?xml version="1.0" ?>
<!-- =================================================================================== -->
<!-- |    This document was autogenerated by xacro from frobo.urdf.xacro               | -->
<!-- |    EDITING THIS FILE BY HAND IS NOT RECOMMENDED                                 | -->
<!-- =================================================================================== -->
<robot name="Frobo">
  <!-- The following included files set up definitions of parts of the robot body -->
  <material name="Black">
    <color rgba="0.2 0.2 0.2 1.0"/>
  </material>
  <material name="Orange">
    <color rgba="1.0  0.55 0.0 1.0"/>
  </material>
  <material name="Brown">
    <color rgba="0.55  0.35 0.15 1.0"/>
  </material>
  <material name="Grey">
    <color rgba="0.75 0.75 0.75 1.0"/>
  </material>
  <material name="Red">
    <color rgba="0.8 0.0 0.0 1.0"/>
  </material>
  <material name="White">
    <color rgba="1.0 1.0 1.0 1.0"/>
  </material>
  <material name="Blue">
    <color rgba="0.0 0.0 0.8 1.0"/>
  </material>
  <!-- Now we can start using the macros included above to define the actual Frobo -->
  <link name="base_link">
    <visual>
      <origin rpy="0 0 0" xyz="0 0 0.074"/>
      <geometry>
        <!-- <mesh filename="package://frobo_description/meshes/base.stl"  /> -->
        <cylinder length="0.006" radius="0.15"/>
      </geometry>
      <material name="Brown"/>
    </visual>
    <collision>
      <origin rpy="0 0 0" xyz="0 0 0.06191"/>
      <geometry>
        <cylinder length="0.12382" radius="0.2"/>
      </geometry>
    </collision>
  </link>
  <joint name="base_l_wheel_joint" type="continuous">
    <axis xyz="0 0 1"/>
    <limit effort="100" velocity="100"/>
    <safety_controller k_velocity="10"/>
    <origin rpy="1.57 0 0" xyz="0 0.116 0.06191"/>
    <parent link="base_link"/>
    <child link="base_l_wheel_link"/>
  </joint>
  <link name="base_l_wheel_link">
    <visual>
      <origin rpy="0 0 0" xyz="0 0 0"/>
      <geometry>
        <cylinder length="0.02032" radius="0.06191"/>
      </geometry>
      <material name="Orange"/>
    </visual>
  </link>
  <joint name="base_r_wheel_joint" type="continuous">
    <axis xyz="0 0 1"/>
    <limit effort="100" velocity="100"/>
    <safety_controller k_velocity="10"/>
    <origin rpy="-1.57 0 0" xyz="0 -0.116 0.06191"/>
    <parent link="base_link"/>
    <child link="base_r_wheel_link"/>
  </joint>
  <link name="base_r_wheel_link">
    <visual>
      <origin rpy="0 0 0" xyz="0 0 0"/>
      <geometry>
        <cylinder length="0.02032" radius="0.06191"/>
      </geometry>
      <material name="Orange"/>
    </visual>
  </link>
  <joint name="base_fr_sonar_joint" type="fixed">
    <origin rpy="1.57 0 -0.6" xyz="0.115 -0.055 0.054"/>
    <parent link="base_link"/>
    <child link="base_fr_sonar_link"/>
  </joint>
  <link name="base_fr_sonar_link">
    <visual>
      <origin rpy="0 0 0" xyz="0 0 0"/>
      <geometry>
        <mesh filename="package://frobo_description/meshes/sonar.stl"/>
      </geometry>
      <material name="Blue"/>
    </visual>
  </link>
  <joint name="base_fc_sonar_joint" type="fixed">
    <origin rpy="1.57 0 0" xyz="0.125 0 0.054"/>
    <parent link="base_link"/>
    <child link="base_fc_sonar_link"/>
  </joint>
  <link name="base_fc_sonar_link">
    <visual>
      <origin rpy="0 0 0" xyz="0 0 0"/>
      <geometry>
        <mesh filename="package://frobo_description/meshes/sonar.stl"/>
      </geometry>
      <material name="Blue"/>
    </visual>
  </link>
  <joint name="base_fl_sonar_joint" type="fixed">
    <origin rpy="1.57 0 0.6" xyz="0.115 0.055 0.054"/>
    <parent link="base_link"/>
    <child link="base_fl_sonar_link"/>
  </joint>
  <link name="base_fl_sonar_link">
    <visual>
      <origin rpy="0 0 0" xyz="0 0 0"/>
      <geometry>
        <mesh filename="package://frobo_description/meshes/sonar.stl"/>
      </geometry>
      <material name="Blue"/>
    </visual>
  </link>
</robot>

